'use strict';
import {fork} from 'child_process';
import test from 'ava';
import getStream from 'get-stream';
import delay from 'delay';

function tick(time) {
	// slow things down for reliable tests on Travis CI
	return delay(process.env.CI ? time * 10 : time);
}

test.cb.beforeEach(t => {
	const child = fork('fixture.js', {silent: true});

	const exit = new Promise((resolve, reject) =>
		child.on('exit', code =>
			(code > 0 ? reject : resolve)(code)
		)
	);

	t.context = {
		// tell the child to create a promise, and reject it
		rejectWithError: (key, message) => child.send({action: 'reject-error', key, message}),
		rejectWithValue: (key, value) => child.send({action: 'reject-value', key, value}),
		rejectWithNothing: key => child.send({action: 'reject-nothing', key}),
		fastExit: () => child.send({action: 'fast-exit'}),

		// tell the child to handle the promise previously rejected
		handle: key => child.send({action: 'handle', key}),

		// tell the child to reinstall loudRejection
		reinstall: () => child.send({action: 'reinstall'}),

		// kill the child (returns a promise for when the child is done)
		kill: () => {
			child.kill();
			return exit;
		},

		// the stdout of the child. Useful for debug
		stdout: getStream(child.stdout),

		// the stderr of the child. This is where unhandledRejections will be logged
		stderr: getStream(child.stderr),

		// promise for when the child has exited
		exit
	};

	child.on('message', message => {
		if (message.status !== 'ready') {
			t.fail(`I got a message I don't understand: ${JSON.stringify(message)}`);
		}

		t.end();
	});
});

test('no rejections', async t => {
	const child = t.context;

	await tick(20);
	await child.kill();

	t.is(await child.stderr, '');
});

test('one unhandled rejection', async t => {
	const child = t.context;

	child.rejectWithError('a', 'foo123');
	await tick(20);
	await child.kill();

	t.true(/foo123/.test(await child.stderr));
});

test('two unhandled rejections', async t => {
	const child = t.context;

	child.rejectWithError('a', 'foo456');
	child.rejectWithError('b', 'bar789');
	await tick(20);
	await child.kill();

	t.true(/foo456/.test(await child.stderr));
	t.true(/bar789/.test(await child.stderr));
});

test('one rejection that is handled before exit', async t => {
	const child = t.context;

	child.rejectWithError('a', 'foo123');
	await tick(20);
	child.handle('a');
	await tick(20);
	await child.kill();

	t.is(await child.stderr, '');
});

test('two rejections, first one handled', async t => {
	const child = t.context;

	child.rejectWithError('a', 'foo987');
	child.rejectWithError('b', 'bar654');
	await tick(20);
	child.handle('a');
	await tick(20);
	await child.kill();

	t.false(/foo987/.test(await child.stderr));
	t.true(/bar654/.test(await child.stderr));
});

test('two rejections, last one handled', async t => {
	const child = t.context;

	child.rejectWithError('a', 'foo987');
	child.rejectWithError('b', 'bar654');
	await tick(20);
	child.handle('b');
	await tick(20);
	await child.kill();

	t.true(/foo987/.test(await child.stderr));
	t.false(/bar654/.test(await child.stderr));
});

test('rejection with a string value', async t => {
	const child = t.context;

	child.rejectWithValue('a', 'foo123');
	await tick(20);
	await child.kill();

	t.true(/Promise rejected with value: foo123/.test(await child.stderr));
});

test('rejection with a falsy value', async t => {
	const child = t.context;

	child.rejectWithValue('a', false);
	child.rejectWithValue('a', 0);
	await tick(20);
	await child.kill();

	t.true(/Promise rejected with value: false/.test(await child.stderr));
	t.true(/Promise rejected with value: 0/.test(await child.stderr));
});

test('rejection with no value', async t => {
	const child = t.context;

	child.rejectWithNothing();
	await tick(20);
	await child.kill();

	t.true(/Promise rejected no value/.test(await child.stderr));
});

test('will warn if installed twice', async t => {
	const child = t.context;

	child.reinstall();
	await tick(20);
	await child.kill();

	t.true(/WARN: loud rejection called more than once/.test(await child.stderr));
});

test('will still produce an error if process exits synchronously after Promise rejection', async t => {
	const child = t.context;

	child.fastExit();
	await child.exit;
});
